Fatal error: exception Failure("'continue' is outside of loop")
